<?xml version="1.0" encoding="utf-8"?>
<robot xmlns:xacro="http://www.ros.org/wiki/xacro" name="arm6">

  <!-- XACRO arguments for configuration -->
  <xacro:arg name="controllers_file" default="$(find arm6)/config/arm_controllers.yaml" />
  <xacro:arg name="use_sim_time" default="true" />
  <xacro:arg name="use_fake_hardware" default="false" />
  
  <!-- Properties -->
  <xacro:property name="controllers_file" value="$(arg controllers_file)" />
  <xacro:property name="use_sim_time" value="$(arg use_sim_time)" />
  <xacro:property name="use_fake_hardware" value="$(arg use_fake_hardware)" />

  <!-- Base Link -->
  <link name="base_link">
    <inertial>
      <origin xyz="0.037793 0.20034 0.065141" rpy="0 0 0" />
      <mass value="2.2693" />
      <inertia
        ixx="0.0064373"
        ixy="-7.9504E-07"
        ixz="3.1948E-06"
        iyy="0.0048913"
        iyz="4.6014E-05"
        izz="0.0063709" />
    </inertial>
    <visual>
      <origin xyz="0 0 0" rpy="0 0 0" />
      <geometry>
        <mesh filename="package://arm6/meshes/base_link.STL" />
      </geometry>
      <material name="">
        <color rgba="0.79216 0.81961 0.93333 1" />
      </material>
    </visual>
    <collision>
      <origin xyz="0 0 0" rpy="0 0 0" />
      <geometry>
        <mesh filename="package://arm6/meshes/base_link.STL" />
      </geometry>
    </collision>
  </link>

  <!-- Link1 -->
  <link name="Link1">
    <inertial>
      <origin xyz="-0.0341557930468132 0.307116971089813 -1.27924045245642E-07" rpy="0 0 0" />
      <mass value="2.58255268807088" />
      <inertia
        ixx="0.0130139121861334"
        ixy="0.00405232491310445"
        ixz="-4.28450891574271E-08"
        iyy="0.00580947647637596"
        iyz="-7.10598430705665E-07"
        izz="0.0142006453008754" />
    </inertial>
    <visual>
      <origin xyz="0 0 0" rpy="0 0 0" />
      <geometry>
        <mesh filename="package://arm6/meshes/Link1.STL" />
      </geometry>
      <material name="">
        <color rgba="0.792156862745098 0.819607843137255 0.933333333333333 1" />
      </material>
    </visual>
    <collision>
      <origin xyz="0 0 0" rpy="0 0 0" />
      <geometry>
        <mesh filename="package://arm6/meshes/Link1.STL" />
      </geometry>
    </collision>
  </link>

  <!-- Joint j1 -->
  <joint name="j1" type="revolute">
    <origin xyz="0.037806 -0.064604 0.11548" rpy="1.5708 0 0" />
    <parent link="base_link" />
    <child link="Link1" />
    <axis xyz="0 -1 0" />
    <limit
      lower="-3.14159"
      upper="3.14159"
      effort="100"
      velocity="2.0" />
  </joint>

  <!-- Link2 -->
  <link name="Link2">
    <inertial>
      <origin xyz="0.0322293481684512 0.2030784412013 -6.20140955672616E-05" rpy="0 0 0" />
      <mass value="3.92598739285493" />
      <inertia
        ixx="0.0795536016923369"
        ixy="0.00173347570780648"
        ixz="3.16793680237356E-06"
        iyy="0.00693922842616741"
        iyz="-2.34355263566876E-05"
        izz="0.0810613241191654" />
    </inertial>
    <visual>
      <origin xyz="0 0 0" rpy="0 0 0" />
      <geometry>
        <mesh filename="package://arm6/meshes/Link2.STL" />
      </geometry>
      <material name="">
        <color rgba="0.792156862745098 0.819607843137255 0.933333333333333 1" />
      </material>
    </visual>
    <collision>
      <origin xyz="0 0 0" rpy="0 0 0" />
      <geometry>
        <mesh filename="package://arm6/meshes/Link2.STL" />
      </geometry>
    </collision>
  </link>

  <!-- Joint j2 -->
  <joint name="j2" type="revolute">
    <origin xyz="0 0.363 0" rpy="0 0 0" />
    <parent link="Link1" />
    <child link="Link2" />
    <axis xyz="1 0 0" />
    <limit
      lower="-3.14159"
      upper="3.14159"
      effort="100"
      velocity="2.0" />
  </joint>

  <!-- Link3 -->
  <link name="Link3">
    <inertial>
      <origin xyz="-0.0291986987675043 0.341653725272601 -0.0863422706938065" rpy="0 0 0" />
      <mass value="1.93910828514451" />
      <inertia
        ixx="0.0107111547199636"
        ixy="0.0016483172358137"
        ixz="0.00333306856931167"
        iyy="0.0103103781174519"
        iyz="-0.00336693383921128"
        izz="0.00560839682066395" />
    </inertial>
    <visual>
      <origin xyz="0 0 0" rpy="0 0 0" />
      <geometry>
        <mesh filename="package://arm6/meshes/Link3.STL" />
      </geometry>
      <material name="">
        <color rgba="0.792156862745098 0.819607843137255 0.933333333333333 1" />
      </material>
    </visual>
    <collision>
      <origin xyz="0 0 0" rpy="0 0 0" />
      <geometry>
        <mesh filename="package://arm6/meshes/Link3.STL" />
      </geometry>
    </collision>
  </link>

  <!-- Joint j3 -->
  <joint name="j3" type="revolute">
    <origin xyz="-0.00025 0 0" rpy="0 0 0" />
    <parent link="Link2" />
    <child link="Link3" />
    <axis xyz="0 1 0" />
    <limit
      lower="-3.14159"
      upper="3.14159"
      effort="100"
      velocity="2.0" />
  </joint>

  <!-- Link4 -->
  <link name="Link4">
    <inertial>
      <origin xyz="-0.0317103196677874 -0.289569373653116 -0.149976650087473" rpy="0 0 0" />
      <mass value="1.48564830223244" />
      <inertia
        ixx="0.0105102634532792"
        ixy="-0.00410287807559147"
        ixz="1.92797036805769E-08"
        iyy="0.00335669837032608"
        iyz="5.33092635492742E-08"
        izz="0.0125216631987523" />
    </inertial>
    <visual>
      <origin xyz="0 0 0" rpy="0 0 0" />
      <geometry>
        <mesh filename="package://arm6/meshes/Link4.STL" />
      </geometry>
      <material name="">
        <color rgba="0.792156862745098 0.819607843137255 0.933333333333333 1" />
      </material>
    </visual>
    <collision>
      <origin xyz="0 0 0" rpy="0 0 0" />
      <geometry>
        <mesh filename="package://arm6/meshes/Link4.STL" />
      </geometry>
    </collision>
  </link>

  <!-- Joint j4 -->
  <joint name="j4" type="revolute">
    <origin xyz="0 0.39 0" rpy="0 0 0" />
    <parent link="Link3" />
    <child link="Link4" />
    <axis xyz="1 0 0" />
    <limit
      lower="-3.14159"
      upper="3.14159"
      effort="100"
      velocity="2.0" />
  </joint>

  <!-- Link5 -->
  <link name="Link5">
    <inertial>
      <origin xyz="-0.00390855102788603 0.0050554928508631 4.67688145711076E-08" rpy="0 0 0" />
      <mass value="0.789456345932932" />
      <inertia
        ixx="0.00139383729966315"
        ixy="-1.46027496755452E-05"
        ixz="2.62607712978387E-09"
        iyy="0.00078077007989036"
        iyz="-7.32441707355258E-10"
        izz="0.00146715996873719" />
    </inertial>
    <visual>
      <origin xyz="0 0 0" rpy="0 0 0" />
      <geometry>
        <mesh filename="package://arm6/meshes/Link5.STL" />
      </geometry>
      <material name="">
        <color rgba="0.792156862745098 0.819607843137255 0.933333333333333 1" />
      </material>
    </visual>
    <collision>
      <origin xyz="0 0 0" rpy="0 0 0" />
      <geometry>
        <mesh filename="package://arm6/meshes/Link5.STL" />
      </geometry>
    </collision>
  </link>

  <!-- Joint j5 -->
  <joint name="j5" type="revolute">
    <origin xyz="0.00025 -0.42574 -0.14998" rpy="0 0 0" />
    <parent link="Link4" />
    <child link="Link5" />
    <axis xyz="-1 0 0" />
    <limit
      lower="-3.14159"
      upper="3.14159"
      effort="100"
      velocity="2.0" />
  </joint>

  <!-- Link6 -->
  <link name="Link6">
    <inertial>
      <origin xyz="0.000639113652415819 0.0107736134383868 4.70014921391537E-05" rpy="0 0 0" />
      <mass value="0.141894854238648" />
      <inertia
        ixx="7.00623194753971E-05"
        ixy="2.98477825869017E-08"
        ixz="2.7709265395048E-07"
        iyy="0.000120209877277034"
        iyz="-8.24265766433744E-09"
        izz="6.76625055908213E-05" />
    </inertial>
    <visual>
      <origin xyz="0 0 0" rpy="0 0 0" />
      <geometry>
        <mesh filename="package://arm6/meshes/Link6.STL" />
      </geometry>
      <material name="">
        <color rgba="0.792156862745098 0.819607843137255 0.933333333333333 1" />
      </material>
    </visual>
    <collision>
      <origin xyz="0 0 0" rpy="0 0 0" />
      <geometry>
        <mesh filename="package://arm6/meshes/Link6.STL" />
      </geometry>
    </collision>
  </link>

  <!-- Joint j6 -->
  <joint name="j6" type="revolute">
    <origin xyz="-0.00025 -0.084 0" rpy="0 0 0" />
    <parent link="Link5" />
    <child link="Link6" />
    <axis xyz="0 -1 0" />
    <limit
      lower="-3.14159"
      upper="3.14159"
      effort="100"
      velocity="2.0" />
  </joint>

  <!-- Gazebo plugin for joint control -->
  <gazebo>
    <plugin name="gazebo_ros2_control" filename="libgazebo_ros2_control.so">
      <parameters>${controllers_file}</parameters>
    </plugin>
  </gazebo>

  <!-- Gazebo material properties -->
  <gazebo reference="base_link">
    <material>Gazebo/Blue</material>
  </gazebo>
  <gazebo reference="Link1">
    <material>Gazebo/Orange</material>
  </gazebo>
  <gazebo reference="Link2">
    <material>Gazebo/Orange</material>
  </gazebo>
  <gazebo reference="Link3">
    <material>Gazebo/Orange</material>
  </gazebo>
  <gazebo reference="Link4">
    <material>Gazebo/Orange</material>
  </gazebo>
  <gazebo reference="Link5">
    <material>Gazebo/Orange</material>
  </gazebo>
  <gazebo reference="Link6">
    <material>Gazebo/Red</material>
  </gazebo>

  <!-- ros2_control hardware interface -->
  <ros2_control name="GazeboSystem" type="system">
    <hardware>
      <xacro:if value="${use_fake_hardware}">
        <plugin>mock_components/GenericSystem</plugin>
        <param name="fake_sensor_commands">false</param>
        <param name="state_following_offset">0.0</param>
      </xacro:if>
      <xacro:unless value="${use_fake_hardware}">
        <plugin>gazebo_ros2_control/GazeboSystem</plugin>
      </xacro:unless>
    </hardware>

    <joint name="j1">
      <command_interface name="position">
        <param name="min">-3.14159</param>
        <param name="max">3.14159</param>
      </command_interface>
      <state_interface name="position"/>
      <state_interface name="velocity"/>
    </joint>

    <joint name="j2">
      <command_interface name="position">
        <param name="min">-3.14159</param>
        <param name="max">3.14159</param>
      </command_interface>
      <state_interface name="position"/>
      <state_interface name="velocity"/>
    </joint>

    <joint name="j3">
      <command_interface name="position">
        <param name="min">-3.14159</param>
        <param name="max">3.14159</param>
      </command_interface>
      <state_interface name="position"/>
      <state_interface name="velocity"/>
    </joint>

    <joint name="j4">
      <command_interface name="position">
        <param name="min">-3.14159</param>
        <param name="max">3.14159</param>
      </command_interface>
      <state_interface name="position"/>
      <state_interface name="velocity"/>
    </joint>

    <joint name="j5">
      <command_interface name="position">
        <param name="min">-3.14159</param>
        <param name="max">3.14159</param>
      </command_interface>
      <state_interface name="position"/>
      <state_interface name="velocity"/>
    </joint>

    <joint name="j6">
      <command_interface name="position">
        <param name="min">-3.14159</param>
        <param name="max">3.14159</param>
      </command_interface>
      <state_interface name="position"/>
      <state_interface name="velocity"/>
    </joint>

  </ros2_control>

</robot>
